<?xml version="1.0" ?>
<sdf version='1.9'>

    <model name='f1d2' canonical_link='base_link'>
        <plugin name='ignition::gazebo::systems::Imu' filename='ignition-gazebo-imu-system'/>
        <plugin name='ignition::gazebo::systems::Sensors' filename='ignition-gazebo-sensors-system'>
            <render_engine>ogre2</render_engine>
        </plugin>

        <pose>0 0 0 0 0 0</pose>
        <link name='base_link'>
            <pose>0.5 0 0.4 0 -0 0</pose>
            <inertial>
                <mass>1.14395</mass>
                <inertia>
                    <ixx>0.126164</ixx>
                    <ixy>0</ixy>
                    <ixz>0</ixz>
                    <iyy>0.41651</iyy>
                    <iyz>0</iyz>
                    <izz>0.481014</izz>
                </inertia>
                <pose>0 0 0 0 -0 0</pose>
            </inertial>
            <visual name='visual'>
                <geometry>
                    <box>
                        <size>1 1 0.5</size>
                    </box>
                </geometry>
                <material>
                    <ambient>0.1 0.1 0.1 1</ambient>
                    <diffuse>0.1 0.1 0.1 1</diffuse>
                    <specular>0.1 0.1 0.1 1</specular>
                </material>
            </visual>
            <collision name='collision'>
                <geometry>
                    <box>
                        <size>1 1 0.5</size>
                    </box>
                </geometry>
                <surface>
                    <friction>
                        <ode/>
                    </friction>
                    <bounce/>
                    <contact/>
                </surface>
            </collision>
            <sensor name='imu_sensor' type='imu'>
                <pose>0 0 0 0 -0 0</pose>
                <topic>imu</topic>
                <update_rate>1</update_rate>
                <enable_metrics>false</enable_metrics>
                <imu>
                    <orientation_reference_frame>
                        <localization>CUSTOM</localization>
                        <custom_rpy>0 0 0</custom_rpy>
                        <grav_dir_x>1 0 0</grav_dir_x>
                    </orientation_reference_frame>
                    <angular_velocity>
                        <x>
                            <noise type='none'>
                                <mean>0</mean>
                                <stddev>0</stddev>
                                <bias_mean>0</bias_mean>
                                <bias_stddev>0</bias_stddev>
                                <dynamic_bias_stddev>0</dynamic_bias_stddev>
                                <dynamic_bias_correlation_time>0</dynamic_bias_correlation_time>
                                <precision>0</precision>
                            </noise>
                        </x>
                        <y>
                            <noise type='none'>
                                <mean>0</mean>
                                <stddev>0</stddev>
                                <bias_mean>0</bias_mean>
                                <bias_stddev>0</bias_stddev>
                                <dynamic_bias_stddev>0</dynamic_bias_stddev>
                                <dynamic_bias_correlation_time>0</dynamic_bias_correlation_time>
                                <precision>0</precision>
                            </noise>
                        </y>
                        <z>
                            <noise type='none'>
                                <mean>0</mean>
                                <stddev>0</stddev>
                                <bias_mean>0</bias_mean>
                                <bias_stddev>0</bias_stddev>
                                <dynamic_bias_stddev>0</dynamic_bias_stddev>
                                <dynamic_bias_correlation_time>0</dynamic_bias_correlation_time>
                                <precision>0</precision>
                            </noise>
                        </z>
                    </angular_velocity>
                    <linear_acceleration>
                        <x>
                            <noise type='none'>
                                <mean>0</mean>
                                <stddev>0</stddev>
                                <bias_mean>0</bias_mean>
                                <bias_stddev>0</bias_stddev>
                                <dynamic_bias_stddev>0</dynamic_bias_stddev>
                                <dynamic_bias_correlation_time>0</dynamic_bias_correlation_time>
                                <precision>0</precision>
                            </noise>
                        </x>
                        <y>
                            <noise type='none'>
                                <mean>0</mean>
                                <stddev>0</stddev>
                                <bias_mean>0</bias_mean>
                                <bias_stddev>0</bias_stddev>
                                <dynamic_bias_stddev>0</dynamic_bias_stddev>
                                <dynamic_bias_correlation_time>0</dynamic_bias_correlation_time>
                                <precision>0</precision>
                            </noise>
                        </y>
                        <z>
                            <noise type='none'>
                                <mean>0</mean>
                                <stddev>0</stddev>
                                <bias_mean>0</bias_mean>
                                <bias_stddev>0</bias_stddev>
                                <dynamic_bias_stddev>0</dynamic_bias_stddev>
                                <dynamic_bias_correlation_time>0</dynamic_bias_correlation_time>
                                <precision>0</precision>
                            </noise>
                        </z>
                    </linear_acceleration>
                    <enable_orientation>true</enable_orientation>
                </imu>
            </sensor>
            <enable_wind>false</enable_wind>
        </link>

        <link name='left_wheel'>
            <pose>-0 0.6 0.4 -1.5707 -0 0</pose>
            <inertial>
                <mass>2</mass>
                <inertia>
                    <ixx>0.145</ixx>
                    <ixy>0</ixy>
                    <ixz>0</ixz>
                    <iyy>0.145</iyy>
                    <iyz>0</iyz>
                    <izz>0.125</izz>
                </inertia>
                <pose>0 0 0 0 -0 0</pose>
            </inertial>
            <visual name='visual'>
                <geometry>
                    <cylinder>
                        <radius>0.4</radius>
                        <length>0.2</length>
                    </cylinder>
                </geometry>
                <material>
                    <ambient>0.1 0.1 0.1 1</ambient>
                    <diffuse>0.1 0.1 0.1 1</diffuse>
                    <specular>0.1 0.1 0.1 1</specular>
                </material>
            </visual>
            <collision name='collision'>
                <geometry>
                    <cylinder>
                        <radius>0.4</radius>
                        <length>0.2</length>
                    </cylinder>
                </geometry>
                <surface>
                    <friction>
                        <ode/>
                    </friction>
                    <bounce/>
                    <contact/>
                </surface>
            </collision>
            <enable_wind>false</enable_wind>
        </link>
        <link name='right_wheel'>
            <pose>-0 -0.6 0.4 -1.5707 -0 0</pose>
            <inertial>
                <mass>1</mass>
                <inertia>
                    <ixx>0.145832</ixx>
                    <ixy>0</ixy>
                    <ixz>0</ixz>
                    <iyy>0.145832</iyy>
                    <iyz>0</iyz>
                    <izz>0.125</izz>
                </inertia>
                <pose>0 0 0 0 -0 0</pose>
            </inertial>
            <visual name='visual'>
                <geometry>
                    <cylinder>
                        <radius>0.4</radius>
                        <length>0.2</length>
                    </cylinder>
                </geometry>
                <material>
                    <ambient>0.1 0.1 0.1 1</ambient>
                    <diffuse>0.1 0.1 0.1 1</diffuse>
                    <specular>0.1 0.1 0.1 1</specular>
                </material>
            </visual>
            <collision name='collision'>
                <geometry>
                    <cylinder>
                        <radius>0.4</radius>
                        <length>0.2</length>
                    </cylinder>
                </geometry>
                <surface>
                    <friction>
                        <ode/>
                    </friction>
                    <bounce/>
                    <contact/>
                </surface>
            </collision>
            <enable_wind>false</enable_wind>
        </link>

        <joint name="lidar_box_joint" type="fixed">
            <parent>base_link</parent>
            <child>lidar_box</child>
        </joint>

        <frame name='lidar_box_frame' attached_to='base_link'>
            <pose>0 0 0.3 0 0 0</pose>
        </frame>
        <link name='lidar_box'>
            <pose relative_to='lidar_box_frame'/>

            <static>true</static>
            <inertial>
                <mass>0.3</mass>
                <inertia>
                    <ixx>0.01</ixx>
                    <ixy>0</ixy>
                    <ixz>0</ixz>
                    <iyy>0.04</iyy>
                    <iyz>0</iyz>
                    <izz>0.04</izz>
                </inertia>
                <pose>0 0 0 0 -0 0</pose>
            </inertial>
            <visual name='visual'>
                <geometry>
                    <box>
                        <size>0.1 0.1 0.1</size>
                    </box>
                </geometry>
                <material>
                    <ambient>0 0 1 1</ambient>
                    <diffuse>0 0 1 1</diffuse>
                    <specular>0 0 1 1</specular>
                </material>
            </visual>
            <collision name='collision'>
                <geometry>
                    <box>
                        <size>0.1 0.1 0.1</size>
                    </box>
                </geometry>
                <surface>
                    <friction>
                        <ode/>
                    </friction>
                    <bounce/>
                    <contact/>
                </surface>
            </collision>
            <sensor name='gpu_lidar' type='gpu_lidar'>

                <!-- <pose>0.8 0 0.5 0 -0 0</pose> -->
                <topic>scan</topic>
                <update_rate>10</update_rate>
                <enable_metrics>false</enable_metrics>
                <lidar>
                    <scan>
                        <horizontal>
                            <samples>640</samples>
                            <resolution>1</resolution>
                            <min_angle>-1.57</min_angle>
                            <max_angle>1.57</max_angle>
                        </horizontal>
                        <vertical>
                            <samples>1</samples>
                            <min_angle>0</min_angle>
                            <max_angle>0</max_angle>
                            <resolution>0.01</resolution>
                        </vertical>
                    </scan>
                    <range>
                        <min>0.08</min>
                        <max>30</max>
                        <resolution>0.01</resolution>
                    </range>
                    <noise>
                        <type>none</type>
                        <mean>0</mean>
                        <stddev>0</stddev>
                    </noise>
                    <visibility_mask>4294967295</visibility_mask>
                </lidar>
            </sensor>

        </link>
        <joint name="camera_box_joint" type="fixed">
            <parent>base_link</parent>
            <child>camera_box</child>
        </joint>
        <frame name='camera_box_frame' attached_to='base_link'>
            <pose>0.5 0 0.15 0 0 0</pose>
        </frame>
        <link name='camera_box'>
            <pose relative_to='camera_box_frame'/>
            <static>true</static>
            <inertial>
                <mass>0.3</mass>
                <inertia>
                    <ixx>0.01</ixx>
                    <ixy>0</ixy>
                    <ixz>0</ixz>
                    <iyy>0.04</iyy>
                    <iyz>0</iyz>
                    <izz>0.04</izz>
                </inertia>
                <pose>0 0 0 0 -0 0</pose>
            </inertial>
            <visual name='visual'>
                <geometry>
                    <box>
                        <size>0.05 0.15 0.05</size>
                    </box>
                </geometry>
                <material>
                    <ambient>0 0 1 1</ambient>
                    <diffuse>0 0 1 1</diffuse>
                    <specular>0 0 1 1</specular>
                </material>
            </visual>
            <collision name='collision'>
                <geometry>
                    <box>
                        <size>0.05 0.15 0.05</size>
                    </box>
                </geometry>
                <surface>
                    <friction>
                        <ode/>
                    </friction>
                    <bounce/>
                    <contact/>
                </surface>
            </collision>
            <sensor name='camera' type='camera'>
                <topic>/camera_front/image_raw</topic>
                <update_rate>10</update_rate>
                <enable_metrics>false</enable_metrics>
                <camera name='__default__'>
                    <pose>0 0 0 0 -0 0</pose>
                    <horizontal_fov>1.396261</horizontal_fov>
                    <image>
                        <width>600</width>
                        <height>600</height>
                        <format>RGB_INT8</format>
                        <anti_aliasing>4</anti_aliasing>
                    </image>
                    <camera_info_topic>__default__</camera_info_topic>
                    <trigger_topic></trigger_topic>
                    <triggered>false</triggered>
                    <clip>
                        <near>0.02</near>
                        <far>300</far>
                    </clip>
                    <save enabled='false'>
                        <path>__default__</path>
                    </save>
                    <visibility_mask>4294967295</visibility_mask>
                    <noise>
                        <type>none</type>
                        <mean>0</mean>
                        <stddev>0</stddev>
                    </noise>
                    <distortion>
                        <k1>0</k1>
                        <k2>0</k2>
                        <k3>0</k3>
                        <p1>0</p1>
                        <p2>0</p2>
                        <center>0.5 0.5</center>
                    </distortion>
                    <lens>
                        <type>stereographic</type>
                        <scale_to_hfov>true</scale_to_hfov>
                        <cutoff_angle>1.5708</cutoff_angle>
                        <env_texture_size>256</env_texture_size>
                    </lens>
                    <optical_frame_id></optical_frame_id>
                </camera>
            </sensor>
            <sensor name='depth_camera' type='depth_camera'>
                <topic>/camera_front/depth_image_raw</topic>
                <update_rate>10</update_rate>
                <enable_metrics>false</enable_metrics>
                <camera name='__default__'>
                    <pose>0 0 0 0 -0 0</pose>
                    <horizontal_fov>1.046</horizontal_fov>
                    <image>
                        <width>320</width>
                        <height>240</height>
                        <format>R_FLOAT32</format>
                        <anti_aliasing>4</anti_aliasing>
                    </image>
                    <camera_info_topic>__default__</camera_info_topic>
                    <trigger_topic></trigger_topic>
                    <triggered>false</triggered>
                    <clip>
                        <near>0.1</near>
                        <far>100</far>
                    </clip>
                    <save enabled='false'>
                        <path>__default__</path>
                    </save>
                    <visibility_mask>4294967295</visibility_mask>
                    <noise>
                        <type>none</type>
                        <mean>0</mean>
                        <stddev>0</stddev>
                    </noise>
                    <distortion>
                        <k1>0</k1>
                        <k2>0</k2>
                        <k3>0</k3>
                        <p1>0</p1>
                        <p2>0</p2>
                        <center>0.5 0.5</center>
                    </distortion>
                    <lens>
                        <type>stereographic</type>
                        <scale_to_hfov>true</scale_to_hfov>
                        <cutoff_angle>1.5708</cutoff_angle>
                        <env_texture_size>256</env_texture_size>
                    </lens>
                    <optical_frame_id></optical_frame_id>
                </camera>
            </sensor>
        </link>
        <frame name='caster_frame' attached_to='base_link'>
            <pose>0.3 0 -0.2 0 0 0</pose>
        </frame>
        <link name='caster'>
            <!-- <pose>0.8 0 0.2 0 -0 0</pose> -->
            <pose relative_to='caster_frame'/>
            <inertial>
                <mass>1</mass>
                <inertia>
                    <ixx>0.1</ixx>

                    <ixy>0</ixy>
                    <ixz>0</ixz>
                    <iyy>0.1</iyy>
                    <iyz>0</iyz>
                    <izz>0.1</izz>
                </inertia>
                <pose>0 0 0 0 -0 0</pose>
            </inertial>
            <visual name='visual'>
                <geometry>
                    <sphere>
                        <radius>0.2</radius>
                    </sphere>
                </geometry>
                <material>
                    <ambient>0.1 0.1 0.1 1</ambient>
                    <diffuse>0.1 0.1 0.1 1</diffuse>
                    <specular>0.1 0.1 0.1 1</specular>
                </material>
            </visual>
            <collision name='collision'>
                <geometry>
                    <sphere>
                        <radius>0.2</radius>
                    </sphere>
                </geometry>
                <surface>
                    <friction>
                        <ode/>
                    </friction>
                    <bounce/>
                    <contact/>
                </surface>
            </collision>
            <enable_wind>false</enable_wind>
        </link>
        <joint name='left_wheel_joint' type='revolute'>
            <pose>0 0 0 0 -0 0</pose>
            <parent>base_link</parent>
            <child>left_wheel</child>
            <axis>
                <xyz>0 9.6e-05 1</xyz>
                <limit>
                    <lower>-1.7976900000000001e+308</lower>
                    <upper>1.7976900000000001e+308</upper>
                    <effort>inf</effort>
                    <velocity>inf</velocity>
                    <stiffness>100000000</stiffness>
                    <dissipation>1</dissipation>
                </limit>
                <dynamics>
                    <spring_reference>0</spring_reference>
                    <spring_stiffness>0</spring_stiffness>
                    <damping>0</damping>
                    <friction>0</friction>
                </dynamics>
            </axis>
        </joint>
        <joint name='right_wheel_joint' type='revolute'>
            <pose>0 0 0 0 -0 0</pose>
            <parent>base_link</parent>
            <child>right_wheel</child>
            <axis>
                <xyz>0 9.6e-05 1</xyz>
                <limit>
                    <lower>-1.7976900000000001e+308</lower>
                    <upper>1.7976900000000001e+308</upper>
                    <effort>inf</effort>
                    <velocity>inf</velocity>
                    <stiffness>100000000</stiffness>
                    <dissipation>1</dissipation>
                </limit>
                <dynamics>
                    <spring_reference>0</spring_reference>
                    <spring_stiffness>0</spring_stiffness>
                    <damping>0</damping>
                    <friction>0</friction>
                </dynamics>
            </axis>
        </joint>
        <joint name='caster_wheel' type='ball'>
            <parent>base_link</parent>
            <child>caster</child>
            <pose>0 0 0 0 -0 0</pose>
        </joint>
        <plugin name='ignition::gazebo::systems::DiffDrive' filename='ignition-gazebo-diff-drive-system'>
            <left_joint>left_wheel_joint</left_joint>
            <right_joint>right_wheel_joint</right_joint>
            <wheel_separation>1.2</wheel_separation>
            <wheel_radius>0.4</wheel_radius>
            <odom_publish_frequency>50</odom_publish_frequency>
            <topic>cmd_vel</topic>
            <frame_id>odom</frame_id>
            <child_frame_id>base_link</child_frame_id>
        </plugin>
        <static>false</static>
        <self_collide>false</self_collide>
    </model>
</sdf>
